Workbook

Sheet Récapitulatif
A1: ÉTUDE D'ÉVÉNEMENT : GUERRE EN UKRAINE (24/02/2022)
A4: Actif | B4: Catégorie | C4: AR J=0 Mean-Adj | D4: AR J=0 Mkt-Adj | E4: AR J=0 Mkt Model | F4: CAR ant. Mean-Adj | G4: CAR ant. Mkt-Adj | H4: CAR ant. Mkt Model | I4: CAR adj. Mean-Adj | J4: CAR adj. Mkt-Adj | K4: CAR adj. Mkt Model | L4: p-val Jour J (Mkt Model)
A5: EU ETS Carbon | B5: Marché Carbone (EU ETS) | C5: ='EU ETS Carbon'!D60 -> -0.086573383 | D5: ='EU ETS Carbon'!E60 -> -0.04853196 | E5: ='EU ETS Carbon'!F60 -> -0.081955876 | F5: ='EU ETS Carbon'!I31 -> 0.032196749 | G5: ='EU ETS Carbon'!J31 -> 0.10554449 | H5: ='EU ETS Carbon'!K31 -> 0.037412626 | I5: ='EU ETS Carbon'!I32 -> -0.082261074 | J5: ='EU ETS Carbon'!J32 -> -0.053858202 | K5: ='EU ETS Carbon'!K32 -> -0.083040334 | L5: ='EU ETS Carbon'!K42 -> 0.0051848841
A6: ERIXX (ENR Europe) | B6: Finance Verte / ENR | C6: ='ERIX (ENR Europe)'!D60 -> 0.091516325 | D6: ='ERIX (ENR Europe)'!E60 -> 0.12589868 | E6: ='ERIX (ENR Europe)'!F60 -> 0.13232384 | F6: ='ERIX (ENR Europe)'!I31 -> -0.0081301732 | G6: ='ERIX (ENR Europe)'!J31 -> 0.028626937 | H6: ='ERIX (ENR Europe)'!K31 -> 0.037965477 | I6: ='ERIX (ENR Europe)'!I32 -> 0.13927917 | J6: ='ERIX (ENR Europe)'!J32 -> 0.16160923 | K6: ='ERIX (ENR Europe)'!K32 -> 0.16836776 | L6: ='ERIX (ENR Europe)'!K42 -> 7.0172507e-06
A7: CLIM (Finance Verte) | B7: Finance Verte / ENR | C7: ='CLIM (Finance Verte)'!D60 -> -0.0039207433 | D7: ='CLIM (Finance Verte)'!E60 -> 0.030862543 | E7: ='CLIM (Finance Verte)'!F60 -> -0.0023209369 | F7: ='CLIM (Finance Verte)'!I31 -> 0.010480333 | G7: ='CLIM (Finance Verte)'!J31 -> 0.051246713 | H7: ='CLIM (Finance Verte)'!K31 -> 0.012287454 | I7: ='CLIM (Finance Verte)'!I32 -> 0.012325687 | J7: ='CLIM (Finance Verte)'!J32 -> 0.038665009 | K7: ='CLIM (Finance Verte)'!K32 -> 0.013466068 | L7: ='CLIM (Finance Verte)'!K42 -> 0.5053563
A8: Brent Oil | B8: Énergies Fossiles | C8: ='Brent Oil'!D60 -> 0.018018536 | D8: ='Brent Oil'!E60 -> 0.059402019 | E8: ='Brent Oil'!F60 -> 0.024493425 | F8: ='Brent Oil'!I31 -> 0.0070320406 | G8: ='Brent Oil'!J31 -> 0.11380038 | H8: ='Brent Oil'!K31 -> 0.014345992 | I8: ='Brent Oil'!I32 -> 0.06516658 | J8: ='Brent Oil'!J32 -> 0.15750786 | K8: ='Brent Oil'!K32 -> 0.069782037 | L8: ='Brent Oil'!K42 -> 0.1036788
A9: TTF Natural Gas | B9: Énergies Fossiles | C9: ='TTF Natural Gas'!D60 -> 0.51713828 | D9: ='TTF Natural Gas'!E60 -> 0.54729019 | E9: ='TTF Natural Gas'!F60 -> 0.4064449 | F9: ='TTF Natural Gas'!I31 -> 0.26240797 | G9: ='TTF Natural Gas'!J31 -> 0.25686064 | H9: ='TTF Natural Gas'!K31 -> 0.13737014 | I9: ='TTF Natural Gas'!I32 -> 0.23346005 | J9: ='TTF Natural Gas'!J32 -> 0.21348567 | K9: ='TTF Natural Gas'!K32 -> 0.15455514 | L9: ='TTF Natural Gas'!K42 -> 2.7028993e-08
A10: Rotterdam Coal | B10: Énergies Fossiles | C10: ='Rotterdam Coal'!D60 -> -4.2458682e-05 | D10: ='Rotterdam Coal'!E60 -> 0.049121855 | E10: ='Rotterdam Coal'!F60 -> -0.0068143899 | F10: ='Rotterdam Coal'!I31 -> -0.11295537 | G10: ='Rotterdam Coal'!J31 -> 0.071621276 | H10: ='Rotterdam Coal'!K31 -> -0.12060486 | I10: ='Rotterdam Coal'!I32 -> 0.69252564 | J10: ='Rotterdam Coal'!J32 -> 0.86267523 | K10: ='Rotterdam Coal'!K32 -> 0.68769845 | L10: ='Rotterdam Coal'!K42 -> 0.78777374
A13: Lecture de nos résultats de l'étude d'événement : Guerre en Ukraine (24/02/2022) Rappel méthodologique - t = 0 : 24 février 2022 (invasion russe de l'Ukraine) - Fenêtre d'estimation : 25 jours ouvrés avant la période d'anticipation → sert à estimer α̂ et γ̂ (Market Model) et θ̂ (Mean-Adjusted) - Fenêtre d'anticipation : [-10, -1] → le marché avait-il anticipé l'événement ? - Fenêtre d'ajustement : [+1, +10] → l'effet persiste-t-il après le choc ? - Test : t = AR / σ ou CAR / (σ·√n), bilatéral, loi de Student (df = 24) - Seuils : |t| > 1.96 → significatif à 5% | |t| > 2.58 → significatif à 1% 1. Marché Carbone, EU ETS (quotas CO₂) AR au jour J ≈ -8.7% (négatif et significatif, p < 5% sur les trois modèles) Contre-intuitif à première vue : le prix des quotas carbone a chuté le jour de l'invasion. L'explication économique : la guerre a immédiatement déclenché une forte incertitude sur la croissance européenne, réduisant les anticipations d'activité industrielle et donc la demande de quotas. Par ailleurs, certains acteurs ont liquidé leurs positions EUA pour couvrir d'autres expositions. La réaction est donc une prime de risque économique à court terme, pas un signal climatique. CAR anticipation ≈ négatif ou non significatif → le marché carbone n'avait pas anticipé l'événement avant J. CAR ajustement → à interpréter : si positif, le marché se rattrape en intégrant la thèse de la transition accélérée. 2. Énergies fossiles Brent Oil : AR ≈ +1.8% (modéré, probablement non significatif) La réaction du pétrole est surprenamment faible. Les marchés avaient déjà en partie intégré le risque géopolitique dans les semaines précédentes (cf. CAR anticipation probablement positif). Le Brent est un marché global, la Russie pèse davantage sur le gaz que sur le pétrole mondial. TTF Natural Gas : AR ≈ +51%, le résultat le plus extrême de l'étude Réaction massive et statistiquement significative (p << 1%). La Russie fournissait environ 40% du gaz européen via Nord Stream et d'autres gazoducs. Le marché a immédiatement pricé le risque de rupture d'approvisionnement. Ce résultat illustre parfaitement la dépendance énergétique européenne au gaz russe et la vulnérabilité du TTF comme point de référence du gaz en Europe. Rotterdam Coal : AR ≈ 0% (non significatif) Le charbon réagit peu le jour J. Paradoxal car le charbon est un substitut au gaz, mais le marché a peut-être anticipé que les contraintes réglementaires européennes (EU ETS, Green Deal) limiteraient le retour au charbon. L'effet charbon sera probablement plus visible dans la fenêtre d'ajustement. 3. Finance verte / Énergies renouvelables ERIX (European Renewable Energy Index) : AR ≈ +9.2% (positif et significatif) Réaction très forte, significative. Le marché interprète immédiatement la guerre comme un accélérateur de la transition énergétique : réduire la dépendance au gaz russe passe par développer massivement les ENR. CLIM : AR ≈ -0.4% (proche de zéro, non significatif) Réaction quasi nulle. CLIM représente sans doute un indice plus large incluant des actifs défensifs ou moins directement liés à l'énergie européenne. L'absence de réaction peut aussi refléter un effet de diversification. | I13: Oui, l'événement a bien provoqué des réactions différenciées entre actifs carbonés et bas-carbone. Les marchés financiers opèrent un ajustement instantané des prix qui révèle leurs anticipations sur la sécurité énergétique et la trajectoire de transition. La guerre agit simultanément comme un choc d'offre fossile (↑ gaz) et comme un signal pro-transition (↑ ENR), ce qui confirme le rôle des marchés dans l'intégration des risques géopolitiques, climatiques et énergétiques.

Sheet EU ETS Carbon
A1: Étude d'événement : Guerre Ukraine (24/02/2022), EU ETS Carbon
A3: Average returns | B3: =AVERAGE(B25:B49) -> 0.0017703412 | C3: Rendement moyen dans la fenêtre d'estimation (θ̂ pour Mean-Adjusted)
A4: Alpha (α̂) | B4: 0.0019909859 | C4: Constante du Market Model estimée par MCO
A5: Beta (γ̂) | B5: 0.13338867 | C5: Pente du Market Model : si le rendement marché varie d'1 unité, l'actif varie de γ̂ unités
A8: Event day | B8: 44616
A9: Anticipation | B9: 10 | C9: jours avant l'événement
A10: Ajustement | B10: 10 | C10: jours après l'événement
A11: Estimation wind | B11: 25 | C11: jours (fenêtre d'estimation MCO)
A24: Date | B24: Rendement EU ETS Carbon | C24: Rendement Euro Stoxx 50 | D24: AR Mean-Adjusted | E24: AR Market-Adjusted | F24: AR Market Model
A25: 44567 | B25: -0.0096286107 | C25: -0.015331864 | D25: =B25-$B$3 -> -0.011398952 | E25: =B25-C25 -> 0.005703253 | F25: =B25-($B$4+$B$5*C25) -> -0.0095744996 | H25: Statistique | I25: Mean-Adjusted | J25: Market-Adjusted | K25: Market Model
A26: 44568 | B26: -0.015162037 | C26: -0.0043886275 | D26: =B26-$B$3 -> -0.016932378 | E26: =B26-C26 -> -0.01077341 | F26: =B26-($B$4+$B$5*C26) -> -0.01656763 | H26: σ (1 jour) | I26: =STDEV($D$25:$D$49) -> 0.026714445 | J26: =STDEV($E$25:$E$49) -> 0.029276004 | K26: =STDEV($F$25:$F$49) -> 0.026649226
A27: 44571 | B27: -0.062169468 | C27: -0.015400064 | D27: =B27-$B$3 -> -0.063939809 | E27: =B27-C27 -> -0.046769404 | F27: =B27-($B$4+$B$5*C27) -> -0.062106259 | H27: σ (10 jours) | I27: =I26*SQRT(10) -> 0.084478493 | J27: =J26*SQRT(10) -> 0.092578853 | K27: =K26*SQRT(10) -> 0.084272252
A28: 44572 | B28: 0.015413534 | C28: 0.009911504 | D28: =B28-$B$3 -> 0.013643193 | E28: =B28-C28 -> 0.0055020299 | F28: =B28-($B$4+$B$5*C28) -> 0.012100466 | H28: σ (21 jours) | I28: =I26*SQRT(21) -> 0.12242097 | J28: =J26*SQRT(21) -> 0.1341595 | K28: =K26*SQRT(21) -> 0.1221221
A29: 44573 | B29: -0.015796619 | C29: 0.0081396174 | D29: =B29-$B$3 -> -0.01756696 | E29: =B29-C29 -> -0.023936236 | F29: =B29-($B$4+$B$5*C29) -> -0.018873337 | H29: Rendements Anormaux Cumulés (CAR)
A30: 44574 | B30: 0.0068965517 | C30: -0.00011357508 | D30: =B30-$B$3 -> 0.0051262105 | E30: =B30-C30 -> 0.0070101268 | F30: =B30-($B$4+$B$5*C30) -> 0.0049207155 | H30: AR Jour J (événement) | I30: =D60 -> -0.086573383 | J30: =E60 -> -0.04853196 | K30: =F60 -> -0.081955876
A31: 44575 | B31: 0.018929016 | C31: -0.010127659 | D31: =B31-$B$3 -> 0.017158675 | E31: =B31-C31 -> 0.029056675 | F31: =B31-($B$4+$B$5*C31) -> 0.018288945 | H31: CAR Anticipation [-10,-1] | I31: =SUM(D50:D59) -> 0.032196749 | J31: =SUM(E50:E59) -> 0.10554449 | K31: =SUM(F50:F59) -> 0.037412626
A32: 44578 | B32: -0.018332926 | C32: 0.0070105018 | D32: =B32-$B$3 -> -0.020103267 | E32: =B32-C32 -> -0.025343428 | F32: =B32-($B$4+$B$5*C32) -> -0.021259033 | H32: CAR Ajustement [+1,+10] | I32: =SUM(D61:D70) -> -0.082261074 | J32: =SUM(E61:E70) -> -0.053858202 | K32: =SUM(F61:F70) -> -0.083040334
A33: 44579 | B33: 0.02564741 | C33: -0.010301922 | D33: =B33-$B$3 -> 0.023877069 | E33: =B33-C33 -> 0.035949332 | F33: =B33-($B$4+$B$5*C33) -> 0.025030584 | H33: CAR Total [-10,+10] | I33: =SUM(D50:D70) -> -0.13663771 | J33: =SUM(E50:E70) -> 0.0031543235 | K33: =SUM(F50:F70) -> -0.12758358
A34: 44580 | B34: -0.0067977664 | C34: 0.0024566472 | D34: =B34-$B$3 -> -0.0085681077 | E34: =B34-C34 -> -0.0092544136 | F34: =B34-($B$4+$B$5*C34) -> -0.0091164412
A35: 44581 | B35: 0.042776827 | C35: 0.0073402119 | D35: =B35-$B$3 -> 0.041006486 | E35: =B35-C35 -> 0.035436615 | F35: =B35-($B$4+$B$5*C35) -> 0.03980674 | H35: Statistiques t
A36: 44582 | B36: -0.013478669 | C36: -0.01629213 | D36: =B36-$B$3 -> -0.01524901 | E36: =B36-C36 -> 0.0028134619 | F36: =B36-($B$4+$B$5*C36) -> -0.013296469 | H36: t - Jour J | I36: =I30/I26 -> -3.2406955 | J36: =J30/J26 -> -1.6577386 | K36: =K30/K26 -> -3.0753567
A37: 44585 | B37: -0.0053463229 | C37: -0.041422736 | D37: =B37-$B$3 -> -0.0071166642 | E37: =B37-C37 -> 0.036076413 | F37: =B37-($B$4+$B$5*C37) -> -0.001811985 | H37: t - Anticipation | I37: =I31/I27 -> 0.38112362 | J37: =J31/J27 -> 1.1400496 | K37: =K31/K27 -> 0.44394952
A38: 44586 | B38: 0.0409699 | C38: 0.0058948642 | D38: =B38-$B$3 -> 0.039199558 | E38: =B38-C38 -> 0.035075035 | F38: =B38-($B$4+$B$5*C38) -> 0.038192606 | H38: t - Ajustement | I38: =I32/I27 -> -0.97375168 | J38: =J32/J27 -> -0.58175491 | K38: =K32/K27 -> -0.98538169
A39: 44587 | B39: 0.013884108 | C39: 0.021170815 | D39: =B39-$B$3 -> 0.012113767 | E39: =B39-C39 -> -0.0072867071 | F39: =B39-($B$4+$B$5*C39) -> 0.0090691751 | H39: t - Total | I39: =I33/I28 -> -1.11613 | J39: =J33/J28 -> 0.023511741 | K39: =K33/K28 -> -1.0447215
A40: 44588 | B40: 0.012449072 | C40: 0.0048912541 | D40: =B40-$B$3 -> 0.010678731 | E40: =B40-C40 -> 0.0075578179 | F40: =B40-($B$4+$B$5*C40) -> 0.0098056482
A41: 44589 | B41: -0.0062597809 | C41: -0.011483967 | D41: =B41-$B$3 -> -0.0080301221 | E41: =B41-C41 -> 0.0052241858 | F41: =B41-($B$4+$B$5*C41) -> -0.0067189357 | H41: p-valeurs (bilatéral, df=24)
A42: 44592 | B42: -0.00011248594 | C42: 0.0091106502 | D42: =B42-$B$3 -> -0.0018828272 | E42: =B42-C42 -> -0.0092231362 | F42: =B42-($B$4+$B$5*C42) -> -0.0033187293 | H42: p - Jour J | I42: 0.0034797626 | J42: 0.11038585 | K42: 0.0051848841
A43: 44593 | B43: 0.0032624592 | C43: 0.011941287 | D43: =B43-$B$3 -> 0.001492118 | E43: =B43-C43 -> -0.0086788277 | F43: =B43-($B$4+$B$5*C43) -> -0.00032135905 | H43: p - Anticipation | I43: 0.70646456 | J43: 0.2655158 | K43: 0.6610561
A44: 44594 | B44: 0.051356806 | C44: -0.00056821374 | D44: =B44-$B$3 -> 0.049586465 | E44: =B44-C44 -> 0.05192502 | F44: =B44-($B$4+$B$5*C44) -> 0.049441614 | H44: p - Ajustement | I44: 0.33989282 | J44: 0.56615665 | K44: 0.3342671
A45: 44595 | B45: 0.006612628 | C45: -0.019192049 | D45: =B45-$B$3 -> 0.0048422867 | E45: =B45-C45 -> 0.025804677 | F45: =B45-($B$4+$B$5*C45) -> 0.007181644 | H45: p - Total | I45: 0.27541717 | J45: 0.98143647 | K45: 0.30656074
A46: 44596 | B46: 0.017482517 | C46: -0.013146505 | D46: =B46-$B$3 -> 0.015712176 | E46: =B46-C46 -> 0.030629023 | F46: =B46-($B$4+$B$5*C46) -> 0.017245127
A47: 44599 | B47: 0.0026033531 | C47: 0.0083150164 | D47: =B47-$B$3 -> 0.00083301188 | E47: =B47-C47 -> -0.0057116633 | F47: =B47-($B$4+$B$5*C47) -> -0.00049676174 | H47: Significatif si p-valeur < 5% (|t| > 1.96) ou < 1% (|t| > 2.58)
A48: 44600 | B48: 0.0020772746 | C48: 0.0021089224 | D48: =B48-$B$3 -> 0.00030693338 | E48: =B48-C48 -> -3.1647784e-05 | F48: =B48-($B$4+$B$5*C48) -> -0.0001950176 | H48: AR > 0 : surperformance liée à l'événement ; AR < 0 : sous-performance
A49: 44601 | B49: -0.063018242 | C49: 0.018124319 | D49: =B49-$B$3 -> -0.064788583 | E49: =B49-C49 -> -0.081142561 | F49: =B49-($B$4+$B$5*C49) -> -0.067426807
A50: 44602 | B50: 0.00011061947 | C50: -0.0016698072 | D50: =B50-$B$3 -> -0.0016597218 | E50: =B50-C50 -> 0.0017804267 | F50: =B50-($B$4+$B$5*C50) -> -0.001657633 | G50: ← Anticipation [-10,-1]
A51: 44603 | B51: 0.023116912 | C51: -0.0099688224 | D51: =B51-$B$3 -> 0.021346571 | E51: =B51-C51 -> 0.033085734 | F51: =B51-($B$4+$B$5*C51) -> 0.022455654
A52: 44606 | B52: -0.012648649 | C52: -0.021847173 | D52: =B52-$B$3 -> -0.01441899 | E52: =B52-C52 -> 0.0091985246 | F52: =B52-($B$4+$B$5*C52) -> -0.011725469
A53: 44607 | B53: -0.0067885689 | C53: 0.019500796 | D53: =B53-$B$3 -> -0.0085589102 | E53: =B53-C53 -> -0.026289365 | F53: =B53-($B$4+$B$5*C53) -> -0.01138074
A54: 44608 | B54: -0.01466211 | C54: -0.001566168 | D54: =B54-$B$3 -> -0.016432451 | E54: =B54-C54 -> -0.013095942 | F54: =B54-($B$4+$B$5*C54) -> -0.016444187
A55: 44609 | B55: -0.03803983 | C55: -0.0058083138 | D55: =B55-$B$3 -> -0.039810171 | E55: =B55-C55 -> -0.032231516 | F55: =B55-($B$4+$B$5*C55) -> -0.039256053
...

Sheet ERIX (ENR Europe)
A1: Étude d'événement : Guerre Ukraine (24/02/2022), ERIXX (ENR Europe)
A3: Average returns | B3: =AVERAGE(B25:B49) -> -0.0018887214 | C3: Rendement moyen dans la fenêtre d'estimation (θ̂ pour Mean-Adjusted)
A4: Alpha (α̂) | B4: 6.1239838e-05 | C4: Constante du Market Model estimée par MCO
A5: Beta (γ̂) | B5: 1.1788312 | C5: Pente du Market Model : si le rendement marché varie d'1 unité, l'actif varie de γ̂ unités
A8: Event day | B8: 44616
A9: Anticipation | B9: 10 | C9: jours avant l'événement
A10: Ajustement | B10: 10 | C10: jours après l'événement
A11: Estimation wind | B11: 25 | C11: jours (fenêtre d'estimation MCO)
A24: Date | B24: Rendement ERIXX (ENR Europe) | C24: Rendement Euro Stoxx 50 | D24: AR Mean-Adjusted | E24: AR Market-Adjusted | F24: AR Market Model
A25: 44567 | B25: -0.040614261 | C25: -0.015331864 | D25: =B25-$B$3 -> -0.03872554 | E25: =B25-C25 -> -0.025282397 | F25: =B25-($B$4+$B$5*C25) -> -0.022601822 | H25: Statistique | I25: Mean-Adjusted | J25: Market-Adjusted | K25: Market Model
A26: 44568 | B26: -0.024501709 | C26: -0.0043886275 | D26: =B26-$B$3 -> -0.022612987 | E26: =B26-C26 -> -0.020113081 | F26: =B26-($B$4+$B$5*C26) -> -0.019389498 | H26: σ (1 jour) | I26: =STDEV($D$25:$D$49) -> 0.028447466 | J26: =STDEV($E$25:$E$49) -> 0.023317188 | K26: =STDEV($F$25:$F$49) -> 0.023182659
A27: 44571 | B27: -0.013937282 | C27: -0.015400064 | D27: =B27-$B$3 -> -0.012048561 | E27: =B27-C27 -> 0.0014627817 | F27: =B27-($B$4+$B$5*C27) -> 0.0041555531 | H27: σ (10 jours) | I27: =I26*SQRT(10) -> 0.089958786 | J27: =J26*SQRT(10) -> 0.073735423 | K27: =K26*SQRT(10) -> 0.073310004
A28: 44572 | B28: 0.0080706143 | C28: 0.009911504 | D28: =B28-$B$3 -> 0.0099593357 | E28: =B28-C28 -> -0.0018408897 | F28: =B28-($B$4+$B$5*C28) -> -0.0036746152 | H28: σ (21 jours) | I28: =I26*SQRT(21) -> 0.13036267 | J28: =J26*SQRT(21) -> 0.10685278 | K28: =K26*SQRT(21) -> 0.10623629
A29: 44573 | B29: 0.0038119321 | C29: 0.0081396174 | D29: =B29-$B$3 -> 0.0057006535 | E29: =B29-C29 -> -0.0043276853 | F29: =B29-($B$4+$B$5*C29) -> -0.0058445423 | H29: Rendements Anormaux Cumulés (CAR)
A30: 44574 | B30: 0.0076513108 | C30: -0.00011357508 | D30: =B30-$B$3 -> 0.0095400322 | E30: =B30-C30 -> 0.0077648859 | F30: =B30-($B$4+$B$5*C30) -> 0.0077239568 | H30: AR Jour J (événement) | I30: =D60 -> 0.091516325 | J30: =E60 -> 0.12589868 | K30: =F60 -> 0.13232384
A31: 44575 | B31: -0.016366452 | C31: -0.010127659 | D31: =B31-$B$3 -> -0.01447773 | E31: =B31-C31 -> -0.0062387932 | F31: =B31-($B$4+$B$5*C31) -> -0.0044888921 | H31: CAR Anticipation [-10,-1] | I31: =SUM(D50:D59) -> -0.0081301732 | J31: =SUM(E50:E59) -> 0.028626937 | K31: =SUM(F50:F59) -> 0.037965477
A32: 44578 | B32: 0.0079424163 | C32: 0.0070105018 | D32: =B32-$B$3 -> 0.0098311377 | E32: =B32-C32 -> 0.00093191449 | F32: =B32-($B$4+$B$5*C32) -> -0.00038302147 | H32: CAR Ajustement [+1,+10] | I32: =SUM(D61:D70) -> 0.13927917 | J32: =SUM(E61:E70) -> 0.16160923 | K32: =SUM(F61:F70) -> 0.16836776
A33: 44579 | B33: -0.019875993 | C33: -0.010301922 | D33: =B33-$B$3 -> -0.017987271 | E33: =B33-C33 -> -0.0095740705 | F33: =B33-($B$4+$B$5*C33) -> -0.0077930058 | H33: CAR Total [-10,+10] | I33: =SUM(D50:D70) -> 0.22266532 | J33: =SUM(E50:E70) -> 0.31613485 | K33: =SUM(F50:F70) -> 0.33865708
A34: 44580 | B34: -0.00058077305 | C34: 0.0024566472 | D34: =B34-$B$3 -> 0.0013079484 | E34: =B34-C34 -> -0.0030374202 | F34: =B34-($B$4+$B$5*C34) -> -0.0035379851
A35: 44581 | B35: 0.04066333 | C35: 0.0073402119 | D35: =B35-$B$3 -> 0.042552052 | E35: =B35-C35 -> 0.033323119 | F35: =B35-($B$4+$B$5*C35) -> 0.03194922 | H35: Statistiques t
A36: 44582 | B36: -0.057395622 | C36: -0.01629213 | D36: =B36-$B$3 -> -0.055506901 | E36: =B36-C36 -> -0.041103492 | F36: =B36-($B$4+$B$5*C36) -> -0.038251191 | H36: t - Jour J | I36: =I30/I26 -> 3.2170291 | J36: =J30/J26 -> 5.399394 | K36: =K30/K26 -> 5.7078804
A37: 44585 | B37: -0.033047412 | C37: -0.041422736 | D37: =B37-$B$3 -> -0.031158691 | E37: =B37-C37 -> 0.0083753243 | F37: =B37-($B$4+$B$5*C37) -> 0.01572176 | H37: t - Anticipation | I37: =I31/I27 -> -0.090376644 | J37: =J31/J27 -> 0.3882386 | K37: =K31/K27 -> 0.51787581
A38: 44586 | B38: -0.016025154 | C38: 0.0058948642 | D38: =B38-$B$3 -> -0.014136433 | E38: =B38-C38 -> -0.021920018 | F38: =B38-($B$4+$B$5*C38) -> -0.023035444 | H38: t - Ajustement | I38: =I32/I27 -> 1.5482554 | J38: =J32/J27 -> 2.1917447 | K38: =K32/K27 -> 2.2966546
A39: 44587 | B39: 0.039174218 | C39: 0.021170815 | D39: =B39-$B$3 -> 0.041062939 | E39: =B39-C39 -> 0.018003403 | F39: =B39-($B$4+$B$5*C39) -> 0.014156162 | H39: t - Total | I39: =I33/I28 -> 1.7080452 | J39: =J33/J28 -> 2.958602 | K39: =K33/K28 -> 3.1877721
A40: 44588 | B40: 0.0075216638 | C40: 0.0048912541 | D40: =B40-$B$3 -> 0.0094103852 | E40: =B40-C40 -> 0.0026304097 | F40: =B40-($B$4+$B$5*C40) -> 0.0016944613
A41: 44589 | B41: -0.021108867 | C41: -0.011483967 | D41: =B41-$B$3 -> -0.019220145 | E41: =B41-C41 -> -0.0096249 | F41: =B41-($B$4+$B$5*C41) -> -0.0076324488 | H41: p-valeurs (bilatéral, df=24)
A42: 44592 | B42: 0.036089048 | C42: 0.0091106502 | D42: =B42-$B$3 -> 0.037977769 | E42: =B42-C42 -> 0.026978398 | F42: =B42-($B$4+$B$5*C42) -> 0.02528789 | H42: p - Jour J | I42: 0.0036854619 | J42: 1.5171235e-05 | K42: 7.0172507e-06
A43: 44593 | B43: -0.012274547 | C43: 0.011941287 | D43: =B43-$B$3 -> -0.010385825 | E43: =B43-C43 -> -0.024215834 | F43: =B43-($B$4+$B$5*C43) -> -0.026412548 | H43: p - Anticipation | I43: 0.92873796 | J43: 0.70126197 | K43: 0.60928619
A44: 44594 | B44: 0.02050248 | C44: -0.00056821374 | D44: =B44-$B$3 -> 0.022391201 | E44: =B44-C44 -> 0.021070694 | F44: =B44-($B$4+$B$5*C44) -> 0.021111068 | H44: p - Ajustement | I44: 0.13464756 | J44: 0.038337919 | K44: 0.03066934
A45: 44595 | B45: -0.030123841 | C45: -0.019192049 | D45: =B45-$B$3 -> -0.02823512 | E45: =B45-C45 -> -0.010931793 | F45: =B45-($B$4+$B$5*C45) -> -0.0075608964 | H45: p - Total | I45: 0.10053273 | J45: 0.0068457069 | K45: 0.0039560189
A46: 44596 | B46: 0.058723518 | C46: -0.013146505 | D46: =B46-$B$3 -> 0.06061224 | E46: =B46-C46 -> 0.071870023 | F46: =B46-($B$4+$B$5*C46) -> 0.074159788
A47: 44599 | B47: -0.0031321838 | C47: 0.0083150164 | D47: =B47-$B$3 -> -0.0012434623 | E47: =B47-C47 -> -0.0114472 | F47: =B47-($B$4+$B$5*C47) -> -0.012995424 | H47: Significatif si p-valeur < 5% (|t| > 1.96) ou < 1% (|t| > 2.58)
A48: 44600 | B48: -0.022144467 | C48: 0.0021089224 | D48: =B48-$B$3 -> -0.020255746 | E48: =B48-C48 -> -0.02425339 | F48: =B48-($B$4+$B$5*C48) -> -0.024691771 | H48: AR > 0 : surperformance liée à l'événement ; AR < 0 : sous-performance
A49: 44601 | B49: 0.033759996 | C49: 0.018124319 | D49: =B49-$B$3 -> 0.035648718 | E49: =B49-C49 -> 0.015635677 | F49: =B49-($B$4+$B$5*C49) -> 0.012333245
A50: 44602 | B50: -0.017659849 | C50: -0.0016698072 | D50: =B50-$B$3 -> -0.015771128 | E50: =B50-C50 -> -0.015990042 | F50: =B50-($B$4+$B$5*C50) -> -0.015752668 | G50: ← Anticipation [-10,-1]
A51: 44603 | B51: -0.0027668339 | C51: -0.0099688224 | D51: =B51-$B$3 -> -0.0008781125 | E51: =B51-C51 -> 0.0072019885 | F51: =B51-($B$4+$B$5*C51) -> 0.0089234846
A52: 44606 | B52: -0.017401161 | C52: -0.021847173 | D52: =B52-$B$3 -> -0.01551244 | E52: =B52-C52 -> 0.0044460122 | F52: =B52-($B$4+$B$5*C52) -> 0.0082917276
A53: 44607 | B53: 0.041336236 | C53: 0.019500796 | D53: =B53-$B$3 -> 0.043224957 | E53: =B53-C53 -> 0.02183544 | F53: =B53-($B$4+$B$5*C53) -> 0.01828685
A54: 44608 | B54: -0.0078287592 | C54: -0.001566168 | D54: =B54-$B$3 -> -0.0059400378 | E54: =B54-C54 -> -0.0062625912 | F54: =B54-($B$4+$B$5*C54) -> -0.0060437514
A55: 44609 | B55: 0.0084885122 | C55: -0.0058083138 | D55: =B55-$B$3 -> 0.010377234 | E55: =B55-C55 -> 0.014296826 | F55: =B55-($B$4+$B$5*C55) -> 0.015274294
...

Sheet CLIM (Finance Verte)
A1: Étude d'événement : Guerre Ukraine (24/02/2022), CLIM (Finance Verte)
A3: Average returns | B3: =AVERAGE(B25:B49) -> -0.0014877945 | C3: Rendement moyen dans la fenêtre d'estimation (θ̂ pour Mean-Adjusted)
A4: Alpha (α̂) | B4: -0.0014113488 | C4: Constante du Market Model estimée par MCO
A5: Beta (γ̂) | B5: 0.04621456 | C5: Pente du Market Model : si le rendement marché varie d'1 unité, l'actif varie de γ̂ unités
A8: Event day | B8: 44616
A9: Anticipation | B9: 10 | C9: jours avant l'événement
A10: Ajustement | B10: 10 | C10: jours après l'événement
A11: Estimation wind | B11: 25 | C11: jours (fenêtre d'estimation MCO)
A24: Date | B24: Rendement CLIM (Finance Verte) | C24: Rendement Euro Stoxx 50 | D24: AR Mean-Adjusted | E24: AR Market-Adjusted | F24: AR Market Model
A25: 44567 | B25: -0.001852538 | C25: -0.015331864 | D25: =B25-$B$3 -> -0.00036474347 | E25: =B25-C25 -> 0.013479326 | F25: =B25-($B$4+$B$5*C25) -> 0.00026736614 | H25: Statistique | I25: Mean-Adjusted | J25: Market-Adjusted | K25: Market Model
A26: 44568 | B26: -0.0011135857 | C26: -0.0043886275 | D26: =B26-$B$3 -> 0.00037420876 | E26: =B26-C26 -> 0.0032750418 | F26: =B26-($B$4+$B$5*C26) -> 0.00050058153 | H26: σ (1 jour) | I26: =STDEV($D$25:$D$49) -> 0.0034924744 | J26: =STDEV($E$25:$E$49) -> 0.013774026 | K26: =STDEV($F$25:$F$49) -> 0.0034321428
A27: 44571 | B27: -0.0024154589 | C27: -0.015400064 | D27: =B27-$B$3 -> -0.00092766443 | E27: =B27-C27 -> 0.012984605 | F27: =B27-($B$4+$B$5*C27) -> -0.00029240297 | H27: σ (10 jours) | I27: =I26*SQRT(10) -> 0.011044174 | J27: =J26*SQRT(10) -> 0.043557295 | K27: =K26*SQRT(10) -> 0.010853389
A28: 44572 | B28: 0.0011175265 | C28: 0.009911504 | D28: =B28-$B$3 -> 0.0026053211 | E28: =B28-C28 -> -0.0087939774 | F28: =B28-($B$4+$B$5*C28) -> 0.0020708195 | H28: σ (21 jours) | I28: =I26*SQRT(21) -> 0.016004528 | J28: =J26*SQRT(21) -> 0.063120517 | K28: =K26*SQRT(21) -> 0.015728054
A29: 44573 | B29: -0.0014883721 | C29: 0.0081396174 | D29: =B29-$B$3 -> -5.775836e-07 | E29: =B29-C29 -> -0.0096279895 | F29: =B29-($B$4+$B$5*C29) -> -0.00045319214 | H29: Rendements Anormaux Cumulés (CAR)
A30: 44574 | B30: 0.0014905906 | C30: -0.00011357508 | D30: =B30-$B$3 -> 0.0029783852 | E30: =B30-C30 -> 0.0016041657 | F30: =B30-($B$4+$B$5*C30) -> 0.0029071883 | H30: AR Jour J (événement) | I30: =D60 -> -0.0039207433 | J30: =E60 -> 0.030862543 | K30: =F60 -> -0.0023209369
A31: 44575 | B31: -0.0029767442 | C31: -0.010127659 | D31: =B31-$B$3 -> -0.0014889497 | E31: =B31-C31 -> 0.0071509145 | F31: =B31-($B$4+$B$5*C31) -> -0.0010973501 | H31: CAR Anticipation [-10,-1] | I31: =SUM(D50:D59) -> 0.010480333 | J31: =SUM(E50:E59) -> 0.051246713 | K31: =SUM(F50:F59) -> 0.012287454
A32: 44578 | B32: 0.00055980593 | C32: 0.0070105018 | D32: =B32-$B$3 -> 0.0020476004 | E32: =B32-C32 -> -0.0064506959 | F32: =B32-($B$4+$B$5*C32) -> 0.0016471675 | H32: CAR Ajustement [+1,+10] | I32: =SUM(D61:D70) -> 0.012325687 | J32: =SUM(E61:E70) -> 0.038665009 | K32: =SUM(F61:F70) -> 0.013466068
A33: 44579 | B33: -0.0026109661 | C33: -0.010301922 | D33: =B33-$B$3 -> -0.0011231715 | E33: =B33-C33 -> 0.007690956 | F33: =B33-($B$4+$B$5*C33) -> -0.00072351848 | H33: CAR Total [-10,+10] | I33: =SUM(D50:D70) -> 0.018885277 | J33: =SUM(E50:E70) -> 0.12077426 | K33: =SUM(F50:F70) -> 0.023432585
A34: 44580 | B34: -0.00056095737 | C34: 0.0024566472 | D34: =B34-$B$3 -> 0.00092683714 | E34: =B34-C34 -> -0.0030176045 | F34: =B34-($B$4+$B$5*C34) -> 0.00073685855
A35: 44581 | B35: 0.0020579981 | C35: 0.0073402119 | D35: =B35-$B$3 -> 0.0035457926 | E35: =B35-C35 -> -0.0052822138 | F35: =B35-($B$4+$B$5*C35) -> 0.0031301222 | H35: Statistiques t
A36: 44582 | B36: 0.0013069455 | C36: -0.01629213 | D36: =B36-$B$3 -> 0.00279474 | E36: =B36-C36 -> 0.017599076 | F36: =B36-($B$4+$B$5*C36) -> 0.0034712279 | H36: t - Jour J | I36: =I30/I26 -> -1.1226262 | J36: =J30/J26 -> 2.2406334 | K36: =K30/K26 -> -0.67623553
A37: 44585 | B37: 0.0031698676 | C37: -0.041422736 | D37: =B37-$B$3 -> 0.0046576621 | E37: =B37-C37 -> 0.044592604 | F37: =B37-($B$4+$B$5*C37) -> 0.0064955499 | H37: t - Anticipation | I37: =I31/I27 -> 0.94894678 | J37: =J31/J27 -> 1.1765357 | K37: =K31/K27 -> 1.1321306
A38: 44586 | B38: -0.0031598513 | C38: 0.0058948642 | D38: =B38-$B$3 -> -0.0016720568 | E38: =B38-C38 -> -0.0090547155 | F38: =B38-($B$4+$B$5*C38) -> -0.0020209311 | H38: t - Ajustement | I38: =I32/I27 -> 1.1160353 | J38: =J32/J27 -> 0.88768158 | K38: =K32/K27 -> 1.2407248
A39: 44587 | B39: -0.0013052396 | C39: 0.021170815 | D39: =B39-$B$3 -> 0.0001825549 | E39: =B39-C39 -> -0.022476055 | F39: =B39-($B$4+$B$5*C39) -> -0.00087229072 | H39: t - Total | I39: =I33/I28 -> 1.1799959 | J39: =J33/J28 -> 1.9133916 | K39: =K33/K28 -> 1.4898591
A40: 44588 | B40: 0.0013069455 | C40: 0.0048912541 | D40: =B40-$B$3 -> 0.00279474 | E40: =B40-C40 -> -0.0035843086 | F40: =B40-($B$4+$B$5*C40) -> 0.0024922471
A41: 44589 | B41: -0.0005593884 | C41: -0.011483967 | D41: =B41-$B$3 -> 0.00092840611 | E41: =B41-C41 -> 0.010924578 | F41: =B41-($B$4+$B$5*C41) -> 0.0013826869 | H41: p-valeurs (bilatéral, df=24)
A42: 44592 | B42: -0.0035447761 | C42: 0.0091106502 | D42: =B42-$B$3 -> -0.0020569816 | E42: =B42-C42 -> -0.012655426 | F42: =B42-($B$4+$B$5*C42) -> -0.002554472 | H42: p - Jour J | I42: 0.27270194 | J42: 0.034570717 | K42: 0.5053563
A43: 44593 | B43: -0.0020595394 | C43: 0.011941287 | D43: =B43-$B$3 -> -0.0005717449 | E43: =B43-C43 -> -0.014000826 | F43: =B43-($B$4+$B$5*C43) -> -0.0012000519 | H43: p - Anticipation | I43: 0.35210609 | J43: 0.25091889 | K43: 0.26876455
A44: 44594 | B44: 0 | C44: -0.00056821374 | D44: =B44-$B$3 -> 0.0014877945 | E44: =B44-C44 -> 0.00056821374 | F44: =B44-($B$4+$B$5*C44) -> 0.0014376085 | H44: p - Ajustement | I44: 0.27545689 | J44: 0.38352201 | K44: 0.22669959
A45: 44595 | B45: -0.012570356 | C45: -0.019192049 | D45: =B45-$B$3 -> -0.011082562 | E45: =B45-C45 -> 0.0066216922 | F45: =B45-($B$4+$B$5*C45) -> -0.010272056 | H45: p - Total | I45: 0.24956608 | J45: 0.06769944 | K45: 0.14928689
A46: 44596 | B46: -0.0093102793 | C46: -0.013146505 | D46: =B46-$B$3 -> -0.0078224848 | E46: =B46-C46 -> 0.0038362259 | F46: =B46-($B$4+$B$5*C46) -> -0.0072913706
A47: 44599 | B47: -0.0038358266 | C47: 0.0083150164 | D47: =B47-$B$3 -> -0.0023480321 | E47: =B47-C47 -> -0.012150843 | F47: =B47-($B$4+$B$5*C47) -> -0.0028087527 | H47: Significatif si p-valeur < 5% (|t| > 1.96) ou < 1% (|t| > 2.58)
A48: 44600 | B48: -0.0015402387 | C48: 0.0021089224 | D48: =B48-$B$3 -> -5.2444228e-05 | E48: =B48-C48 -> -0.0036491611 | F48: =B48-($B$4+$B$5*C48) -> -0.00022635287 | H48: AR > 0 : surperformance liée à l'événement ; AR < 0 : sous-performance
A49: 44601 | B49: 0.0026995758 | C49: 0.018124319 | D49: =B49-$B$3 -> 0.0041873703 | E49: =B49-C49 -> -0.015424743 | F49: =B49-($B$4+$B$5*C49) -> 0.0032733171
A50: 44602 | B50: -0.0046153846 | C50: -0.0016698072 | D50: =B50-$B$3 -> -0.0031275901 | E50: =B50-C50 -> -0.0029455774 | F50: =B50-($B$4+$B$5*C50) -> -0.0031268664 | G50: ← Anticipation [-10,-1]
A51: 44603 | B51: -0.0030911901 | C51: -0.0099688224 | D51: =B51-$B$3 -> -0.0016033956 | E51: =B51-C51 -> 0.0068776323 | F51: =B51-($B$4+$B$5*C51) -> -0.0012191366
A52: 44606 | B52: 0.0011627907 | C52: -0.021847173 | D52: =B52-$B$3 -> 0.0026505852 | E52: =B52-C52 -> 0.023009964 | F52: =B52-($B$4+$B$5*C52) -> 0.003583797
A53: 44607 | B53: -0.00077429346 | C53: 0.019500796 | D53: =B53-$B$3 -> 0.00071350105 | E53: =B53-C53 -> -0.02027509 | F53: =B53-($B$4+$B$5*C53) -> -0.00026416538
A54: 44608 | B54: -0.00038744673 | C54: -0.001566168 | D54: =B54-$B$3 -> 0.0011003478 | E54: =B54-C54 -> 0.0011787213 | F54: =B54-($B$4+$B$5*C54) -> 0.0010962818
A55: 44609 | B55: 0.0058139535 | C55: -0.0058083138 | D55: =B55-$B$3 -> 0.007301748 | E55: =B55-C55 -> 0.011622267 | F55: =B55-($B$4+$B$5*C55) -> 0.0074937309
...

Sheet Brent Oil
A1: Étude d'événement : Guerre Ukraine (24/02/2022), Brent Oil
A3: Average returns | B3: =AVERAGE(B25:B49) -> 0.0051124013 | C3: Rendement moyen dans la fenêtre d'estimation (θ̂ pour Mean-Adjusted)
A4: Alpha (α̂) | B4: 0.0054217998 | C4: Constante du Market Model estimée par MCO
A5: Beta (γ̂) | B5: 0.18704397 | C5: Pente du Market Model : si le rendement marché varie d'1 unité, l'actif varie de γ̂ unités
A8: Event day | B8: 44616
A9: Anticipation | B9: 10 | C9: jours avant l'événement
A10: Ajustement | B10: 10 | C10: jours après l'événement
A11: Estimation wind | B11: 25 | C11: jours (fenêtre d'estimation MCO)
A24: Date | B24: Rendement Brent Oil | C24: Rendement Euro Stoxx 50 | D24: AR Mean-Adjusted | E24: AR Market-Adjusted | F24: AR Market Model
A25: 44567 | B25: 0.014727723 | C25: -0.015331864 | D25: =B25-$B$3 -> 0.0096153214 | E25: =B25-C25 -> 0.030059586 | F25: =B25-($B$4+$B$5*C25) -> 0.012173656 | H25: Statistique | I25: Mean-Adjusted | J25: Market-Adjusted | K25: Market Model
A26: 44568 | B26: -0.0029271862 | C26: -0.0043886275 | D26: =B26-$B$3 -> -0.0080395876 | E26: =B26-C26 -> 0.0014614413 | F26: =B26-($B$4+$B$5*C26) -> -0.0075281197 | H26: σ (1 jour) | I26: =STDEV($D$25:$D$49) -> 0.014714308 | J26: =STDEV($E$25:$E$49) -> 0.018410407 | K26: =STDEV($F$25:$F$49) -> 0.0144799
A27: 44571 | B27: -0.010764526 | C27: -0.015400064 | D27: =B27-$B$3 -> -0.015876927 | E27: =B27-C27 -> 0.004635538 | F27: =B27-($B$4+$B$5*C27) -> -0.013305837 | H27: σ (10 jours) | I27: =I26*SQRT(10) -> 0.046530728 | J27: =J26*SQRT(10) -> 0.058218819 | K27: =K26*SQRT(10) -> 0.045789463
A28: 44572 | B28: 0.035241746 | C28: 0.009911504 | D28: =B28-$B$3 -> 0.030129345 | E28: =B28-C28 -> 0.025330242 | F28: =B28-($B$4+$B$5*C28) -> 0.027966059 | H28: σ (21 jours) | I28: =I26*SQRT(21) -> 0.067429431 | J28: =J26*SQRT(21) -> 0.084367084 | K28: =K26*SQRT(21) -> 0.066355237
A29: 44573 | B29: 0.011347348 | C29: 0.0081396174 | D29: =B29-$B$3 -> 0.006234947 | E29: =B29-C29 -> 0.0032077309 | F29: =B29-($B$4+$B$5*C29) -> 0.0044030822 | H29: Rendements Anormaux Cumulés (CAR)
A30: 44574 | B30: -0.0023621117 | C30: -0.00011357508 | D30: =B30-$B$3 -> -0.0074745131 | E30: =B30-C30 -> -0.0022485366 | F30: =B30-($B$4+$B$5*C30) -> -0.007762668 | H30: AR Jour J (événement) | I30: =D60 -> 0.018018536 | J30: =E60 -> 0.059402019 | K30: =F60 -> 0.024493425
A31: 44575 | B31: 0.018823251 | C31: -0.010127659 | D31: =B31-$B$3 -> 0.01371085 | E31: =B31-C31 -> 0.028950909 | F31: =B31-($B$4+$B$5*C31) -> 0.015295769 | H31: CAR Anticipation [-10,-1] | I31: =SUM(D50:D59) -> 0.0070320406 | J31: =SUM(E50:E59) -> 0.11380038 | K31: =SUM(F50:F59) -> 0.014345992
A32: 44578 | B32: 0.0048803161 | C32: 0.0070105018 | D32: =B32-$B$3 -> -0.00023208529 | E32: =B32-C32 -> -0.0021301858 | F32: =B32-($B$4+$B$5*C32) -> -0.0018527558 | H32: CAR Ajustement [+1,+10] | I32: =SUM(D61:D70) -> 0.06516658 | J32: =SUM(E61:E70) -> 0.15750786 | K32: =SUM(F61:F70) -> 0.069782037
A33: 44579 | B33: 0.011910268 | C33: -0.010301922 | D33: =B33-$B$3 -> 0.0067978669 | E33: =B33-C33 -> 0.02221219 | F33: =B33-($B$4+$B$5*C33) -> 0.0084153809 | H33: CAR Total [-10,+10] | I33: =SUM(D50:D70) -> 0.090217156 | J33: =SUM(E50:E70) -> 0.33071026 | K33: =SUM(F50:F70) -> 0.10862145
A34: 44580 | B34: 0.010627357 | C34: 0.0024566472 | D34: =B34-$B$3 -> 0.0055149555 | E34: =B34-C34 -> 0.0081707097 | F34: =B34-($B$4+$B$5*C34) -> 0.0047460561
A35: 44581 | B35: -0.00067842605 | C35: 0.0073402119 | D35: =B35-$B$3 -> -0.0057908274 | E35: =B35-C35 -> -0.008018638 | F35: =B35-($B$4+$B$5*C35) -> -0.0074731682 | H35: Statistiques t
A36: 44582 | B36: -0.0055442408 | C36: -0.01629213 | D36: =B36-$B$3 -> -0.010656642 | E36: =B36-C36 -> 0.01074789 | F36: =B36-($B$4+$B$5*C36) -> -0.0079186957 | H36: t - Jour J | I36: =I30/I26 -> 1.2245589 | J36: =J30/J26 -> 3.2265456 | K36: =K30/K26 -> 1.6915466
A37: 44585 | B37: -0.018432131 | C37: -0.041422736 | D37: =B37-$B$3 -> -0.023544532 | E37: =B37-C37 -> 0.022990605 | F37: =B37-($B$4+$B$5*C37) -> -0.016106058 | H37: t - Anticipation | I37: =I31/I27 -> 0.15112681 | J37: =J31/J27 -> 1.9547009 | K37: =K31/K27 -> 0.31330334
A38: 44586 | B38: 0.022371624 | C38: 0.0058948642 | D38: =B38-$B$3 -> 0.017259223 | E38: =B38-C38 -> 0.01647676 | F38: =B38-($B$4+$B$5*C38) -> 0.015847225 | H38: t - Ajustement | I38: =I32/I27 -> 1.4005063 | J38: =J32/J27 -> 2.7054458 | K38: =K32/K27 -> 1.5239759
A39: 44587 | B39: 0.019954649 | C39: 0.021170815 | D39: =B39-$B$3 -> 0.014842247 | E39: =B39-C39 -> -0.0012161664 | F39: =B39-($B$4+$B$5*C39) -> 0.010572975 | H39: t - Total | I39: =I33/I28 -> 1.3379493 | J39: =J33/J28 -> 3.9198967 | K39: =K33/K28 -> 1.6369688
A40: 44588 | B40: -0.006891952 | C40: 0.0048912541 | D40: =B40-$B$3 -> -0.012004353 | E40: =B40-C40 -> -0.011783206 | F40: =B40-($B$4+$B$5*C40) -> -0.013228631
A41: 44589 | B41: 0.0077233042 | C41: -0.011483967 | D41: =B41-$B$3 -> 0.0026109029 | E41: =B41-C41 -> 0.019207271 | F41: =B41-($B$4+$B$5*C41) -> 0.0044495112 | H41: p-valeurs (bilatéral, df=24)
A42: 44592 | B42: 0.013106742 | C42: 0.0091106502 | D42: =B42-$B$3 -> 0.0079943409 | E42: =B42-C42 -> 0.003996092 | F42: =B42-($B$4+$B$5*C42) -> 0.0059808502 | H42: p - Jour J | I42: 0.23262583 | J42: 0.0036013735 | K42: 0.1036788
A43: 44593 | B43: -0.022475606 | C43: 0.011941287 | D43: =B43-$B$3 -> -0.027588007 | E43: =B43-C43 -> -0.034416893 | F43: =B43-($B$4+$B$5*C43) -> -0.030130951 | H43: p - Anticipation | I43: 0.88113879 | J43: 0.062363088 | K43: 0.75675684
A44: 44594 | B44: 0.0034768955 | C44: -0.00056821374 | D44: =B44-$B$3 -> -0.0016355059 | E44: =B44-C44 -> 0.0040451092 | F44: =B44-($B$4+$B$5*C44) -> -0.0018386233 | H44: p - Ajustement | I44: 0.17415838 | J44: 0.012351444 | K44: 0.14058455
A45: 44595 | B45: 0.018330167 | C45: -0.019192049 | D45: =B45-$B$3 -> 0.013217765 | E45: =B45-C45 -> 0.037522215 | F45: =B45-($B$4+$B$5*C45) -> 0.016498124 | H45: p - Total | I45: 0.1934532 | J45: 0.00064496914 | K45: 0.11468429
A46: 44596 | B46: 0.023707606 | C46: -0.013146505 | D46: =B46-$B$3 -> 0.018595205 | E46: =B46-C46 -> 0.036854111 | F46: =B46-($B$4+$B$5*C46) -> 0.020744781
A47: 44599 | B47: -0.0062185054 | C47: 0.0083150164 | D47: =B47-$B$3 -> -0.011330907 | E47: =B47-C47 -> -0.014533522 | F47: =B47-($B$4+$B$5*C47) -> -0.013195579 | H47: Significatif si p-valeur < 5% (|t| > 1.96) ou < 1% (|t| > 2.58)
A48: 44600 | B48: -0.020606322 | C48: 0.0021089224 | D48: =B48-$B$3 -> -0.025718723 | E48: =B48-C48 -> -0.022715245 | F48: =B48-($B$4+$B$5*C48) -> -0.026422583 | H48: AR > 0 : surperformance liée à l'événement ; AR < 0 : sous-performance
A49: 44601 | B49: 0.0084820445 | C49: 0.018124319 | D49: =B49-$B$3 -> 0.0033696432 | E49: =B49-C49 -> -0.0096422744 | F49: =B49-($B$4+$B$5*C49) -> -0.00032979988
A50: 44602 | B50: -0.001529219 | C50: -0.0016698072 | D50: =B50-$B$3 -> -0.0066416204 | E50: =B50-C50 -> 0.0001405882 | F50: =B50-($B$4+$B$5*C50) -> -0.0066386914 | G50: ← Anticipation [-10,-1]
A51: 44603 | B51: 0.033147358 | C51: -0.0099688224 | D51: =B51-$B$3 -> 0.028034957 | E51: =B51-C51 -> 0.04311618 | F51: =B51-($B$4+$B$5*C51) -> 0.029590166
A52: 44606 | B52: 0.021601017 | C52: -0.021847173 | D52: =B52-$B$3 -> 0.016488615 | E52: =B52-C52 -> 0.04344819 | F52: =B52-($B$4+$B$5*C52) -> 0.020265599
A53: 44607 | B53: -0.033167496 | C53: 0.019500796 | D53: =B53-$B$3 -> -0.038279897 | E53: =B53-C53 -> -0.052668292 | F53: =B53-($B$4+$B$5*C53) -> -0.042236802
A54: 44608 | B54: 0.01640223 | C54: -0.001566168 | D54: =B54-$B$3 -> 0.011289829 | E54: =B54-C54 -> 0.017968398 | F54: =B54-($B$4+$B$5*C54) -> 0.011273372
A55: 44609 | B55: -0.019407236 | C55: -0.0058083138 | D55: =B55-$B$3 -> -0.024519637 | E55: =B55-C55 -> -0.013598922 | F55: =B55-($B$4+$B$5*C55) -> -0.023742625
...

Sheet TTF Natural Gas
A1: Étude d'événement : Guerre Ukraine (24/02/2022), TTF Natural Gas
A3: Average returns | B3: =AVERAGE(B25:B49) -> -0.006119165 | C3: Rendement moyen dans la fenêtre d'estimation (θ̂ pour Mean-Adjusted)
A4: Alpha (α̂) | B4: -0.011408577 | C4: Constante du Market Model estimée par MCO
A5: Beta (γ̂) | B5: -3.1976657 | C5: Pente du Market Model : si le rendement marché varie d'1 unité, l'actif varie de γ̂ unités
A8: Event day | B8: 44616
A9: Anticipation | B9: 10 | C9: jours avant l'événement
A10: Ajustement | B10: 10 | C10: jours après l'événement
A11: Estimation wind | B11: 25 | C11: jours (fenêtre d'estimation MCO)
A24: Date | B24: Rendement TTF Natural Gas | C24: Rendement Euro Stoxx 50 | D24: AR Mean-Adjusted | E24: AR Market-Adjusted | F24: AR Market Model
A25: 44567 | B25: 0.054413147 | C25: -0.015331864 | D25: =B25-$B$3 -> 0.060532312 | E25: =B25-C25 -> 0.06974501 | F25: =B25-($B$4+$B$5*C25) -> 0.01679555 | H25: Statistique | I25: Mean-Adjusted | J25: Market-Adjusted | K25: Market Model
A26: 44568 | B26: -0.08629873 | C26: -0.0043886275 | D26: =B26-$B$3 -> -0.080179565 | E26: =B26-C26 -> -0.081910102 | F26: =B26-($B$4+$B$5*C26) -> -0.088923516 | H26: σ (1 jour) | I26: =STDEV($D$25:$D$49) -> 0.067354196 | J26: =STDEV($E$25:$E$49) -> 0.077350888 | K26: =STDEV($F$25:$F$49) -> 0.0503637
A27: 44571 | B27: -0.040454102 | C27: -0.015400064 | D27: =B27-$B$3 -> -0.034334937 | E27: =B27-C27 -> -0.025054038 | F27: =B27-($B$4+$B$5*C27) -> -0.078289781 | H27: σ (10 jours) | I27: =I26*SQRT(10) -> 0.21299267 | J27: =J26*SQRT(10) -> 0.24460498 | K27: =K26*SQRT(10) -> 0.159264
A28: 44572 | B28: -0.069391422 | C28: 0.009911504 | D28: =B28-$B$3 -> -0.063272257 | E28: =B28-C28 -> -0.079302925 | F28: =B28-($B$4+$B$5*C28) -> -0.026289168 | H28: σ (21 jours) | I28: =I26*SQRT(21) -> 0.3086557 | J28: =J26*SQRT(21) -> 0.3544663 | K28: =K26*SQRT(21) -> 0.23079547
A29: 44573 | B29: -0.045506503 | C29: 0.0081396174 | D29: =B29-$B$3 -> -0.039387338 | E29: =B29-C29 -> -0.05364612 | F29: =B29-($B$4+$B$5*C29) -> -0.0080701502 | H29: Rendements Anormaux Cumulés (CAR)
A30: 44574 | B30: 0.13714689 | C30: -0.00011357508 | D30: =B30-$B$3 -> 0.14326605 | E30: =B30-C30 -> 0.13726046 | F30: =B30-($B$4+$B$5*C30) -> 0.14819229 | H30: AR Jour J (événement) | I30: =D60 -> 0.51713828 | J30: =E60 -> 0.54729019 | K30: =F60 -> 0.4064449
A31: 44575 | B31: 0.017669085 | C31: -0.010127659 | D31: =B31-$B$3 -> 0.02378825 | E31: =B31-C31 -> 0.027796744 | F31: =B31-($B$4+$B$5*C31) -> -0.003307204 | H31: CAR Anticipation [-10,-1] | I31: =SUM(D50:D59) -> 0.26240797 | J31: =SUM(E50:E59) -> 0.25686064 | K31: =SUM(F50:F59) -> 0.13737014
A32: 44578 | B32: -0.11449925 | C32: 0.0070105018 | D32: =B32-$B$3 -> -0.10838009 | E32: =B32-C32 -> -0.12150975 | F32: =B32-($B$4+$B$5*C32) -> -0.080673434 | H32: CAR Ajustement [+1,+10] | I32: =SUM(D61:D70) -> 0.23346005 | J32: =SUM(E61:E70) -> 0.21348567 | K32: =SUM(F61:F70) -> 0.15455514
A33: 44579 | B33: 0.017166156 | C33: -0.010301922 | D33: =B33-$B$3 -> 0.023285321 | E33: =B33-C33 -> 0.027468078 | F33: =B33-($B$4+$B$5*C33) -> -0.0043673693 | H33: CAR Total [-10,+10] | I33: =SUM(D50:D70) -> 1.0130063 | J33: =SUM(E50:E70) -> 1.0176365 | K33: =SUM(F50:F70) -> 0.69837018
A34: 44580 | B34: -0.034876299 | C34: 0.0024566472 | D34: =B34-$B$3 -> -0.028757134 | E34: =B34-C34 -> -0.037332946 | F34: =B34-($B$4+$B$5*C34) -> -0.015612185
A35: 44581 | B35: -0.0052776382 | C35: 0.0073402119 | D35: =B35-$B$3 -> 0.00084152681 | E35: =B35-C35 -> -0.01261785 | F35: =B35-($B$4+$B$5*C35) -> 0.029602483 | H35: Statistiques t
A36: 44582 | B36: 0.05022406 | C36: -0.01629213 | D36: =B36-$B$3 -> 0.056343225 | E36: =B36-C36 -> 0.066516191 | F36: =B36-($B$4+$B$5*C36) -> 0.0095358514 | H36: t - Jour J | I36: =I30/I26 -> 7.6778925 | J36: =J30/J26 -> 7.0754223 | K36: =K30/K26 -> 8.0701954
A37: 44585 | B37: 0.17751329 | C37: -0.041422736 | D37: =B37-$B$3 -> 0.18363246 | E37: =B37-C37 -> 0.21893603 | F37: =B37-($B$4+$B$5*C37) -> 0.05646581 | H37: t - Anticipation | I37: =I31/I27 -> 1.2320047 | J37: =J31/J27 -> 1.0501039 | K37: =K31/K27 -> 0.86253102
A38: 44586 | B38: 0.0062580645 | C38: 0.0058948642 | D38: =B38-$B$3 -> 0.012377229 | E38: =B38-C38 -> 0.00036320029 | F38: =B38-($B$4+$B$5*C38) -> 0.036516447 | H38: t - Ajustement | I38: =I32/I27 -> 1.0960943 | J38: =J32/J27 -> 0.87277726 | K38: =K32/K27 -> 0.97043358
A39: 44587 | B39: -0.018646748 | C39: 0.021170815 | D39: =B39-$B$3 -> -0.012527583 | E39: =B39-C39 -> -0.039817563 | F39: =B39-($B$4+$B$5*C39) -> 0.060459017 | H39: t - Total | I39: =I33/I28 -> 3.2819944 | J39: =J33/J28 -> 2.8708978 | K39: =K33/K28 -> 3.0259268
A40: 44588 | B40: 0.0050524298 | C40: 0.0048912541 | D40: =B40-$B$3 -> 0.011171595 | E40: =B40-C40 -> 0.00016117578 | F40: =B40-($B$4+$B$5*C40) -> 0.032101603
A41: 44589 | B41: -0.0025893544 | C41: -0.011483967 | D41: =B41-$B$3 -> 0.0035298106 | E41: =B41-C41 -> 0.0088946123 | F41: =B41-($B$4+$B$5*C41) -> -0.027902663 | H41: p-valeurs (bilatéral, df=24)
A42: 44592 | B42: -0.080271991 | C42: 0.0091106502 | D42: =B42-$B$3 -> -0.074152826 | E42: =B42-C42 -> -0.089382641 | F42: =B42-($B$4+$B$5*C42) -> -0.0397306 | H42: p - Jour J | I42: 6.4810058e-08 | J42: 2.5827341e-07 | K42: 2.7028993e-08
A43: 44593 | B43: -0.10044643 | C43: 0.011941287 | D43: =B43-$B$3 -> -0.094327264 | E43: =B43-C43 -> -0.11238772 | F43: =B43-($B$4+$B$5*C43) -> -0.050853608 | H43: p - Anticipation | I43: 0.22988191 | J43: 0.30413 | K43: 0.39693257
A44: 44594 | B44: 0.01554479 | C44: -0.00056821374 | D44: =B44-$B$3 -> 0.021663955 | E44: =B44-C44 -> 0.016113003 | F44: =B44-($B$4+$B$5*C44) -> 0.02513641 | H44: p - Ajustement | I44: 0.28391486 | J44: 0.39143321 | K44: 0.34150964
A45: 44595 | B45: 0.037129449 | C45: -0.019192049 | D45: =B45-$B$3 -> 0.043248614 | E45: =B45-C45 -> 0.056321498 | F45: =B45-($B$4+$B$5*C45) -> -0.012831729 | H45: p - Total | I45: 0.0031471001 | J45: 0.0084156798 | K45: 0.0058345152
A46: 44596 | B46: 0.0302781 | C46: -0.013146505 | D46: =B46-$B$3 -> 0.036397265 | E46: =B46-C46 -> 0.043424605 | F46: =B46-($B$4+$B$5*C46) -> -0.00035145134
A47: 44599 | B47: -0.036986401 | C47: 0.0083150164 | D47: =B47-$B$3 -> -0.030867236 | E47: =B47-C47 -> -0.045301417 | F47: =B47-($B$4+$B$5*C47) -> 0.0010108193 | H47: Significatif si p-valeur < 5% (|t| > 1.96) ou < 1% (|t| > 2.58)
A48: 44600 | B48: -0.028833469 | C48: 0.0021089224 | D48: =B48-$B$3 -> -0.022714304 | E48: =B48-C48 -> -0.030942392 | F48: =B48-($B$4+$B$5*C48) -> -0.010681263 | H48: AR > 0 : surperformance liée à l'événement ; AR < 0 : sous-performance
A49: 44601 | B49: -0.037296248 | C49: 0.018124319 | D49: =B49-$B$3 -> -0.031177083 | E49: =B49-C49 -> -0.055420567 | F49: =B49-($B$4+$B$5*C49) -> 0.032067842
A50: 44602 | B50: -0.00086001854 | C50: -0.0016698072 | D50: =B50-$B$3 -> 0.0052591464 | E50: =B50-C50 -> 0.00080978867 | F50: =B50-($B$4+$B$5*C50) -> 0.0052090737 | G50: ← Anticipation [-10,-1]
A51: 44603 | B51: 0.041329872 | C51: -0.0099688224 | D51: =B51-$B$3 -> 0.047449037 | E51: =B51-C51 -> 0.051298695 | F51: =B51-($B$4+$B$5*C51) -> 0.020861489
A52: 44606 | B52: 0.043202542 | C52: -0.021847173 | D52: =B52-$B$3 -> 0.049321707 | E52: =B52-C52 -> 0.065049715 | F52: =B52-($B$4+$B$5*C52) -> -0.015248837
A53: 44607 | B53: -0.12197447 | C53: 0.019500796 | D53: =B53-$B$3 -> -0.11585531 | E53: =B53-C53 -> -0.14147527 | F53: =B53-($B$4+$B$5*C53) -> -0.048208867
A54: 44608 | B54: -0.015849067 | C54: -0.001566168 | D54: =B54-$B$3 -> -0.0097299023 | E54: =B54-C54 -> -0.014282899 | F54: =B54-($B$4+$B$5*C54) -> -0.0094485715
A55: 44609 | B55: 0.073343363 | C55: -0.0058083138 | D55: =B55-$B$3 -> 0.079462528 | E55: =B55-C55 -> 0.079151677 | F55: =B55-($B$4+$B$5*C55) -> 0.066178894
...

Sheet Rotterdam Coal
A1: Étude d'événement : Guerre Ukraine (24/02/2022), Rotterdam Coal
A3: Average returns | B3: =AVERAGE(B25:B49) -> 0.012893232 | C3: Rendement moyen dans la fenêtre d'estimation (θ̂ pour Mean-Adjusted)
A4: Alpha (α̂) | B4: 0.01256964 | C4: Constante du Market Model estimée par MCO
A5: Beta (γ̂) | B5: -0.19562482 | C5: Pente du Market Model : si le rendement marché varie d'1 unité, l'actif varie de γ̂ unités
A8: Event day | B8: 44616
A9: Anticipation | B9: 10 | C9: jours avant l'événement
A10: Ajustement | B10: 10 | C10: jours après l'événement
A11: Estimation wind | B11: 25 | C11: jours (fenêtre d'estimation MCO)
A24: Date | B24: Rendement Rotterdam Coal | C24: Rendement Euro Stoxx 50 | D24: AR Mean-Adjusted | E24: AR Market-Adjusted | F24: AR Market Model
A25: 44567 | B25: 0.045156591 | C25: -0.015331864 | D25: =B25-$B$3 -> 0.032263359 | E25: =B25-C25 -> 0.060488455 | F25: =B25-($B$4+$B$5*C25) -> 0.029587658 | H25: Statistique | I25: Mean-Adjusted | J25: Market-Adjusted | K25: Market Model
A26: 44568 | B26: -0.022996516 | C26: -0.0043886275 | D26: =B26-$B$3 -> -0.035889748 | E26: =B26-C26 -> -0.018607888 | F26: =B26-($B$4+$B$5*C26) -> -0.03642468 | H26: σ (1 jour) | I26: =STDEV($D$25:$D$49) -> 0.02518084 | J26: =STDEV($E$25:$E$49) -> 0.03010335 | K26: =STDEV($F$25:$F$49) -> 0.025031761
A27: 44571 | B27: -0.011768902 | C27: -0.015400064 | D27: =B27-$B$3 -> -0.024662134 | E27: =B27-C27 -> 0.0036311624 | F27: =B27-($B$4+$B$5*C27) -> -0.027351176 | H27: σ (10 jours) | I27: =I26*SQRT(10) -> 0.079628809 | J27: =J26*SQRT(10) -> 0.09519515 | K27: =K26*SQRT(10) -> 0.079157379
A28: 44572 | B28: -0.018404908 | C28: 0.009911504 | D28: =B28-$B$3 -> -0.03129814 | E28: =B28-C28 -> -0.028316412 | F28: =B28-($B$4+$B$5*C28) -> -0.029035612 | H28: σ (21 jours) | I28: =I26*SQRT(21) -> 0.11539311 | J28: =J26*SQRT(21) -> 0.13795088 | K28: =K26*SQRT(21) -> 0.11470994
A29: 44573 | B29: 0.022058824 | C29: 0.0081396174 | D29: =B29-$B$3 -> 0.0091655912 | E29: =B29-C29 -> 0.013919206 | F29: =B29-($B$4+$B$5*C29) -> 0.011081495 | H29: Rendements Anormaux Cumulés (CAR)
A30: 44574 | B30: 0.071223022 | C30: -0.00011357508 | D30: =B30-$B$3 -> 0.058329789 | E30: =B30-C30 -> 0.071336597 | F30: =B30-($B$4+$B$5*C30) -> 0.058631164 | H30: AR Jour J (événement) | I30: =D60 -> -4.2458682e-05 | J30: =E60 -> 0.049121855 | K30: =F60 -> -0.0068143899
A31: 44575 | B31: 0.034251175 | C31: -0.010127659 | D31: =B31-$B$3 -> 0.021357943 | E31: =B31-C31 -> 0.044378834 | F31: =B31-($B$4+$B$5*C31) -> 0.019700314 | H31: CAR Anticipation [-10,-1] | I31: =SUM(D50:D59) -> -0.11295537 | J31: =SUM(E50:E59) -> 0.071621276 | K31: =SUM(F50:F59) -> -0.12060486
A32: 44578 | B32: 0.012987013 | C32: 0.0070105018 | D32: =B32-$B$3 -> 9.3780636e-05 | E32: =B32-C32 -> 0.0059765112 | F32: =B32-($B$4+$B$5*C32) -> 0.0017888012 | H32: CAR Ajustement [+1,+10] | I32: =SUM(D61:D70) -> 0.69252564 | J32: =SUM(E61:E70) -> 0.86267523 | K32: =SUM(F61:F70) -> 0.68769845
A33: 44579 | B33: 0.040384615 | C33: -0.010301922 | D33: =B33-$B$3 -> 0.027491383 | E33: =B33-C33 -> 0.050686537 | F33: =B33-($B$4+$B$5*C33) -> 0.025799664 | H33: CAR Total [-10,+10] | I33: =SUM(D50:D70) -> 0.57952781 | J33: =SUM(E50:E70) -> 0.98341836 | K33: =SUM(F50:F70) -> 0.5602792
A34: 44580 | B34: -0.0033887862 | C34: 0.0024566472 | D34: =B34-$B$3 -> -0.016282019 | E34: =B34-C34 -> -0.0058454333 | F34: =B34-($B$4+$B$5*C34) -> -0.015477845
A35: 44581 | B35: -0.013910355 | C35: 0.0073402119 | D35: =B35-$B$3 -> -0.026803588 | E35: =B35-C35 -> -0.021250567 | F35: =B35-($B$4+$B$5*C35) -> -0.025044068 | H35: Statistiques t
A36: 44582 | B36: 0.015987461 | C36: -0.01629213 | D36: =B36-$B$3 -> 0.0030942285 | E36: =B36-C36 -> 0.032279591 | F36: =B36-($B$4+$B$5*C36) -> 0.00023067581 | H36: t - Jour J | I36: =I30/I26 -> -0.0016861503 | J36: =J30/J26 -> 1.6317737 | K36: =K30/K26 -> -0.27222975
A37: 44585 | B37: 0.0074051219 | C37: -0.041422736 | D37: =B37-$B$3 -> -0.0054881105 | E37: =B37-C37 -> 0.048827858 | F37: =B37-($B$4+$B$5*C37) -> -0.013267833 | H37: t - Anticipation | I37: =I31/I27 -> -1.4185239 | J37: =J31/J27 -> 0.75236265 | K37: =K31/K27 -> -1.5236086
A38: 44586 | B38: 0.0082695253 | C38: 0.0058948642 | D38: =B38-$B$3 -> -0.0046237071 | E38: =B38-C38 -> 0.002374661 | F38: =B38-($B$4+$B$5*C38) -> -0.0031469329 | H38: t - Ajustement | I38: =I32/I27 -> 8.6969233 | J38: =J32/J27 -> 9.0621763 | K38: =K32/K27 -> 8.6877365
A39: 44587 | B39: 0.0082017011 | C39: 0.021170815 | D39: =B39-$B$3 -> -0.0046915313 | E39: =B39-C39 -> -0.012969114 | F39: =B39-($B$4+$B$5*C39) -> -0.000226402 | H39: t - Total | I39: =I33/I28 -> 5.0222048 | J39: =J33/J28 -> 7.1287575 | K39: =K33/K28 -> 4.8843126
A40: 44588 | B40: 0 | C40: 0.0048912541 | D40: =B40-$B$3 -> -0.012893232 | E40: =B40-C40 -> -0.0048912541 | F40: =B40-($B$4+$B$5*C40) -> -0.011612789
A41: 44589 | B41: 0.0033142513 | C41: -0.011483967 | D41: =B41-$B$3 -> -0.0095789811 | E41: =B41-C41 -> 0.014798218 | F41: =B41-($B$4+$B$5*C41) -> -0.011501938 | H41: p-valeurs (bilatéral, df=24)
A42: 44592 | B42: 0.070570571 | C42: 0.0091106502 | D42: =B42-$B$3 -> 0.057677338 | E42: =B42-C42 -> 0.06145992 | F42: =B42-($B$4+$B$5*C42) -> 0.0597832 | H42: p - Jour J | I42: 0.99866858 | J42: 0.11578109 | K42: 0.78777374
A43: 44593 | B43: -0.021037868 | C43: 0.011941287 | D43: =B43-$B$3 -> -0.033931101 | E43: =B43-C43 -> -0.032979155 | F43: =B43-($B$4+$B$5*C43) -> -0.031271496 | H43: p - Anticipation | I43: 0.16889379 | J43: 0.45914909 | K43: 0.14067599
A44: 44594 | B44: 0.016045845 | C44: -0.00056821374 | D44: =B44-$B$3 -> 0.0031526129 | E44: =B44-C44 -> 0.016614059 | F44: =B44-($B$4+$B$5*C44) -> 0.0033650486 | H44: p - Ajustement | I44: 6.9744606e-09 | J44: 3.2437043e-09 | K44: 7.1116603e-09
A45: 44595 | B45: 0.00084602369 | C45: -0.019192049 | D45: =B45-$B$3 -> -0.012047209 | E45: =B45-C45 -> 0.020038072 | F45: =B45-($B$4+$B$5*C45) -> -0.015478057 | H45: p - Total | I45: 3.9294455e-05 | J45: 2.2808678e-07 | K45: 5.5744789e-05
A46: 44596 | B46: 0.031276416 | C46: -0.013146505 | D46: =B46-$B$3 -> 0.018383184 | E46: =B46-C46 -> 0.044422921 | F46: =B46-($B$4+$B$5*C46) -> 0.016134993
A47: 44599 | B47: -0.0027322404 | C47: 0.0083150164 | D47: =B47-$B$3 -> -0.015625473 | E47: =B47-C47 -> -0.011047257 | F47: =B47-($B$4+$B$5*C47) -> -0.013675257 | H47: Significatif si p-valeur < 5% (|t| > 1.96) ou < 1% (|t| > 2.58)
A48: 44600 | B48: 0.019726027 | C48: 0.0021089224 | D48: =B48-$B$3 -> 0.006832795 | E48: =B48-C48 -> 0.017617105 | F48: =B48-($B$4+$B$5*C48) -> 0.007568945 | H48: AR > 0 : surperformance liée à l'événement ; AR < 0 : sous-performance
A49: 44601 | B49: 0.008866201 | C49: 0.018124319 | D49: =B49-$B$3 -> -0.0040270314 | E49: =B49-C49 -> -0.0092581179 | F49: =B49-($B$4+$B$5*C49) -> -0.00015787237
A50: 44602 | B50: 0.0021304927 | C50: -0.0016698072 | D50: =B50-$B$3 -> -0.01076274 | E50: =B50-C50 -> 0.0038002999 | F50: =B50-($B$4+$B$5*C50) -> -0.010765803 | G50: ← Anticipation [-10,-1]
A51: 44603 | B51: 0.0071751262 | C51: -0.0099688224 | D51: =B51-$B$3 -> -0.0057181061 | E51: =B51-C51 -> 0.017143949 | F51: =B51-($B$4+$B$5*C51) -> -0.0073446628
A52: 44606 | B52: 0.0044854881 | C52: -0.021847173 | D52: =B52-$B$3 -> -0.0084077442 | E52: =B52-C52 -> 0.026332661 | F52: =B52-($B$4+$B$5*C52) -> -0.012358001
A53: 44607 | B53: -0.019437878 | C53: 0.019500796 | D53: =B53-$B$3 -> -0.03233111 | E53: =B53-C53 -> -0.038938674 | F53: =B53-($B$4+$B$5*C53) -> -0.028192678
A54: 44608 | B54: -0.016072864 | C54: -0.001566168 | D54: =B54-$B$3 -> -0.028966096 | E54: =B54-C54 -> -0.014506696 | F54: =B54-($B$4+$B$5*C54) -> -0.028948885
A55: 44609 | B55: -0.0032670841 | C55: -0.0058083138 | D55: =B55-$B$3 -> -0.016160316 | E55: =B55-C55 -> 0.0025412297 | F55: =B55-($B$4+$B$5*C55) -> -0.016972974
...
